Workbook
Name inc_pop_den: inc_pop_den!$A$1:$H$81

Sheet Facility List
A1: Site Name | B1: Permit Number | C1: RN | D1: Region | E1: Region Name
A2: CITY OF TULIA MUNICIPAL SOLID WASTE LANDFILL | B2: 1009A | C2: RN102335312 | D2: Region 1 | E2: AMARILLO
A3: CITY OF DALHART LANDFILL | B3: 1038A | C3: RN102121381 | D3: Region 1 | E3: AMARILLO
A4: CITY OF PANHANDLE MUNICIPAL SOLID WASTE LANDFILL | B4: 1164 | C4: RN101503621 | D4: Region 1 | E4: AMARILLO
A5: SOUTHWEST LANDFILL TX LP | B5: 1663C | C5: RN102064151 | D5: Region 1 | E5: AMARILLO
A6: CITY OF BOOKER LANDFILL | B6: 1943 | C6: RN101478121 | D6: Region 1 | E6: AMARILLO
A7: CITY OF PAMPA LANDFILL | B7: 2238 | C7: RN100211416 | D7: Region 1 | E7: AMARILLO
A8: CITY OF CHILDRESS MUNICIPAL SOLID WASTE LANDFILL | B8: 2263 | C8: RN102328101 | D8: Region 1 | E8: AMARILLO
A9: CITY OF MEMPHIS LANDFILL | B9: 2266 | C9: RN102118957 | D9: Region 1 | E9: AMARILLO
A10: CITY OF DUMAS LANDFILL | B10: 2279 | C10: RN102335627 | D10: Region 1 | E10: AMARILLO
A11: CITY OF SHAMROCK MUNICIPAL LANDFILL | B11: 2281A | C11: RN101507325 | D11: Region 1 | E11: AMARILLO
A12: CITY OF SPEARMAN MUNICIPAL SOLID WASTE LANDFILL | B12: 2352 | C12: RN102754496 | D12: Region 1 | E12: AMARILLO
... A156: ZAPATA COUNTY LANDFILL | B156: 783A | C156: RN102327574 | D156: Region 16 | E156: LAREDO

Sheet Landfill-County
A1: Site Name | B1: Permit Number | C1: RN | D1: Counties
A2: CITY OF TULIA MUNICIPAL SOLID WASTE LANDFILL | B2: 1009A | C2: RN102335312 | D2: BRISCOE
D3: SWISHER
A4: CITY OF DALHART LANDFILL | B4: 1038A | C4: RN102121381 | D4: HARTLEY
D5: DALLAM
A6: CITY OF PANHANDLE MUNICIPAL SOLID WASTE LANDFILL | B6: 1164 | C6: RN101503621 | D6: CARSON
A7: SOUTHWEST LANDFILL TX LP | B7: 1663C | C7: RN102064151 | D7: ARMSTRONG
D8: BRISCOE
D9: CARSON
D10: CHILDRESS
D11: COLLINGSWORTH
D12: DALLAM
D13: DEAF SMITH
D14: DONLEY
D15: FLOYD
D16: GRAY
D17: HALL
D18: HANSFORD
D19: HARTLEY
... D28: RANDALL
A29: CITY OF BOOKER LANDFILL | B29: 1943 | C29: RN101478121 | D29: LIPSCOMB
A30: CITY OF PAMPA LANDFILL | B30: 2238 | C30: RN100211416 | D30: DONLEY
D31: GRAY
D32: ROBERTS
D33: HUTCHINSON
D34: LIPSCOMB
D35: HEMPHILL
A36: CITY OF CHILDRESS MUNICIPAL SOLID WASTE LANDFILL | B36: 2263 | C36: RN102328101 | D36: CHILDRESS
A37: CITY OF MEMPHIS LANDFILL | B37: 2266 | C37: RN102118957 | D37: HALL
D38: DONLEY
A39: CITY OF DUMAS LANDFILL | B39: 2279 | C39: RN102335627 | D39: MOORE
A40: CITY OF SHAMROCK MUNICIPAL LANDFILL | B40: 2281A | C40: RN101507325 | D40: WHEELER
A41: CITY OF SPEARMAN MUNICIPAL SOLID WASTE LANDFILL | B41: 2352 | C41: RN102754496 | D41: HANSFORD
D42: OCHILTREE
D43: MOORE
A44: CITY OF DIMMITT MUNICIPAL SOLID WASTE LANDFILL | B44: 445A | C44: RN102071602 | D44: CASTRO
A45: CITY OF MCLEAN LANDFILL | B45: 570 | C45: RN101505204 | D45: GRAY
A46: CITY OF AMARILLO LANDFILL | B46: 73A | C46: RN100237551 | D46: POTTER
D47: RANDALL
A48: PERRYTON MUNICIPAL SOLID WASTE LANDFILL | B48: 876A | C48: RN101999274 | D48: OCHILTREE
...

Sheet Region-County
A1: County | B1: CFIPS | C1: Region | D1: Region Name
A2: Anderson | B2: 001 | C2: Region 5 | D2: Tyler
A3: Andrews | B3: 003 | C3: Region 7 | D3: Midland
A4: Angelina | B4: 005 | C4: Region 10 | D4: Beaumont
A5: Aransas | B5: 007 | C5: Region 14 | D5: Corpus Christi
A6: Archer | B6: 009 | C6: Region 3 | D6: Abilene
A7: Armstrong | B7: 011 | C7: Region 1 | D7: Amarillo
A8: Atascosa | B8: 013 | C8: Region 13 | D8: San Antonio
A9: Austin | B9: 015 | C9: Region 12 | D9: Houston
A10: Bailey | B10: 017 | C10: Region 2 | D10: Lubbock
A11: Bandera | B11: 019 | C11: Region 13 | D11: San Antonio
A12: Bastrop | B12: 021 | C12: Region 11 | D12: Austin
... A255: Zavala | B255: 507 | C255: Region 16 | D255: Laredo

Sheet Municipal Waste
A1: Site Name | B1: Permit Number | C1: RN | D1: Year | E1: Municipal | F1: Region
A2: CITY OF TULIA MUNICIPAL SOLID WASTE LANDFILL | B2: 1009A | C2: RN102335312 | D2: 2017 | E2: 5742.44 | F2: =VLOOKUP(B2,'Facility List'!$B$2:$E$156,3,0) -> Region 1
A3: CITY OF TULIA MUNICIPAL SOLID WASTE LANDFILL | B3: 1009A | C3: RN102335312 | D3: 2018 | E3: 6078.27 | F3: =VLOOKUP(B3,'Facility List'!$B$2:$E$156,3,0) -> Region 1
A4: CITY OF TULIA MUNICIPAL SOLID WASTE LANDFILL | B4: 1009A | C4: RN102335312 | D4: 2019 | E4: 5474.74 | F4: =VLOOKUP(B4,'Facility List'!$B$2:$E$156,3,0) -> Region 1
A5: CITY OF TULIA MUNICIPAL SOLID WASTE LANDFILL | B5: 1009A | C5: RN102335312 | D5: 2020 | E5: 6705.06 | F5: =VLOOKUP(B5,'Facility List'!$B$2:$E$156,3,0) -> Region 1
A6: CITY OF TULIA MUNICIPAL SOLID WASTE LANDFILL | B6: 1009A | C6: RN102335312 | D6: 2021 | E6: 6977.39 | F6: =VLOOKUP(B6,'Facility List'!$B$2:$E$156,3,0) -> Region 1
A7: CITY OF DALHART LANDFILL | B7: 1038A | C7: RN102121381 | D7: 2017 | E7: 7511.17 | F7: =VLOOKUP(B7,'Facility List'!$B$2:$E$156,3,0) -> Region 1
A8: CITY OF DALHART LANDFILL | B8: 1038A | C8: RN102121381 | D8: 2018 | E8: 6584.71 | F8: =VLOOKUP(B8,'Facility List'!$B$2:$E$156,3,0) -> Region 1
A9: CITY OF DALHART LANDFILL | B9: 1038A | C9: RN102121381 | D9: 2019 | E9: 7558 | F9: =VLOOKUP(B9,'Facility List'!$B$2:$E$156,3,0) -> Region 1
A10: CITY OF DALHART LANDFILL | B10: 1038A | C10: RN102121381 | D10: 2020 | E10: 7353.5 | F10: =VLOOKUP(B10,'Facility List'!$B$2:$E$156,3,0) -> Region 1
A11: CITY OF DALHART LANDFILL | B11: 1038A | C11: RN102121381 | D11: 2021 | E11: 7329.09 | F11: =VLOOKUP(B11,'Facility List'!$B$2:$E$156,3,0) -> Region 1
A12: CITY OF PANHANDLE MUNICIPAL SOLID WASTE LANDFILL | B12: 1164 | C12: RN101503621 | D12: 2017 | E12: 2555 | F12: =VLOOKUP(B12,'Facility List'!$B$2:$E$156,3,0) -> Region 1
A13: CITY OF PANHANDLE MUNICIPAL SOLID WASTE LANDFILL | B13: 1164 | C13: RN101503621 | D13: 2018 | E13: 2370 | F13: =VLOOKUP(B13,'Facility List'!$B$2:$E$156,3,0) -> Region 1
... A263: HILLSIDE LANDFILL AND RECYCLING CENTER | B263: 523B | C263: RN100217512 | D263: 2018 | E263: 12163 | F263: =VLOOKUP(B263,'Facility List'!$B$2:$E$156,3,0) -> Region 4
A264: HILLSIDE LANDFILL AND RECYCLING CENTER | B264: 523B | C264: RN100217512 | D264: 2019 | F264: =VLOOKUP(B264,'Facility List'!$B$2:$E$156,3,0) -> Region 4
A265: HILLSIDE LANDFILL AND RECYCLING CENTER | B265: 523B | C265: RN100217512 | D265: 2020 | E265: 47389 | F265: =VLOOKUP(B265,'Facility List'!$B$2:$E$156,3,0) -> Region 4
A266: HILLSIDE LANDFILL AND RECYCLING CENTER | B266: 523B | C266: RN100217512 | D266: 2021 | E266: 74896 | F266: =VLOOKUP(B266,'Facility List'!$B$2:$E$156,3,0) -> Region 4
A267: MCCOMMAS BLUFF LANDFILL | B267: 62 | C267: RN100752146 | D267: 2017 | E267: 1578023.7 | F267: =VLOOKUP(B267,'Facility List'!$B$2:$E$156,3,0) -> Region 4
A268: MCCOMMAS BLUFF LANDFILL | B268: 62 | C268: RN100752146 | D268: 2018 | E268: 1355217.1 | F268: =VLOOKUP(B268,'Facility List'!$B$2:$E$156,3,0) -> Region 4
A269: MCCOMMAS BLUFF LANDFILL | B269: 62 | C269: RN100752146 | D269: 2019 | E269: 1390834.7 | F269: =VLOOKUP(B269,'Facility List'!$B$2:$E$156,3,0) -> Region 4
A270: MCCOMMAS BLUFF LANDFILL | B270: 62 | C270: RN100752146 | D270: 2020 | E270: 1389898.4 | F270: =VLOOKUP(B270,'Facility List'!$B$2:$E$156,3,0) -> Region 4
A271: MCCOMMAS BLUFF LANDFILL | B271: 62 | C271: RN100752146 | D271: 2021 | E271: 1294832 | F271: =VLOOKUP(B271,'Facility List'!$B$2:$E$156,3,0) -> Region 4
A272: CITY OF GRAND PRAIRIE LANDFILL | B272: 996C | C272: RN100542216 | D272: 2017 | E272: 220204.09 | F272: =VLOOKUP(B272,'Facility List'!$B$2:$E$156,3,0) -> Region 4
A273: CITY OF GRAND PRAIRIE LANDFILL | B273: 996C | C273: RN100542216 | D273: 2018 | E273: 220993.91 | F273: =VLOOKUP(B273,'Facility List'!$B$2:$E$156,3,0) -> Region 4
A274: CITY OF GRAND PRAIRIE LANDFILL | B274: 996C | C274: RN100542216 | D274: 2019 | E274: 244008.63 | F274: =VLOOKUP(B274,'Facility List'!$B$2:$E$156,3,0) -> Region 4
A275: CITY OF GRAND PRAIRIE LANDFILL | B275: 996C | C275: RN100542216 | D275: 2020 | E275: 241280.75 | F275: =VLOOKUP(B275,'Facility List'!$B$2:$E$156,3,0) -> Region 4
A276: CITY OF GRAND PRAIRIE LANDFILL | B276: 996C | C276: RN100542216 | D276: 2021 | E276: 261304.18 | F276: =VLOOKUP(B276,'Facility List'!$B$2:$E$156,3,0) -> Region 4
... A336: HUDSPETH COUNTY LANDFILL | B336: 495 | C336: RN100627660 | D336: 2021 | E336: 925 | F336: =VLOOKUP(B336,'Facility List'!$B$2:$E$156,3,0) -> Region 6
A337: CITY OF VAN HORN LANDFILL | B337: 693A | C337: RN102143500 | D337: 2017 | F337: =VLOOKUP(B337,'Facility List'!$B$2:$E$156,3,0) -> Region 6
A338: CITY OF VAN HORN LANDFILL | B338: 693A | C338: RN102143500 | D338: 2018 | F338: =VLOOKUP(B338,'Facility List'!$B$2:$E$156,3,0) -> Region 6
A339: CITY OF VAN HORN LANDFILL | B339: 693A | C339: RN102143500 | D339: 2019 | F339: =VLOOKUP(B339,'Facility List'!$B$2:$E$156,3,0) -> Region 6
A340: CITY OF VAN HORN LANDFILL | B340: 693A | C340: RN102143500 | D340: 2020 | F340: =VLOOKUP(B340,'Facility List'!$B$2:$E$156,3,0) -> Region 6
A341: CITY OF VAN HORN LANDFILL | B341: 693A | C341: RN102143500 | D341: 2021 | E341: 3478.1 | F341: =VLOOKUP(B341,'Facility List'!$B$2:$E$156,3,0) -> Region 6
A342: MCCOMBS LANDFILL | B342: 729B | C342: RN100215599 | D342: 2017 | E342: 2.4 | F342: =VLOOKUP(B342,'Facility List'!$B$2:$E$156,3,0) -> Region 6
A343: MCCOMBS LANDFILL | B343: 729B | C343: RN100215599 | D343: 2018 | E343: 2 | F343: =VLOOKUP(B343,'Facility List'!$B$2:$E$156,3,0) -> Region 6
A344: MCCOMBS LANDFILL | B344: 729B | C344: RN100215599 | D344: 2019 | E344: 3 | F344: =VLOOKUP(B344,'Facility List'!$B$2:$E$156,3,0) -> Region 6
A345: MCCOMBS LANDFILL | B345: 729B | C345: RN100215599 | D345: 2020 | E345: 2 | F345: =VLOOKUP(B345,'Facility List'!$B$2:$E$156,3,0) -> Region 6
A346: MCCOMBS LANDFILL | B346: 729B | C346: RN100215599 | D346: 2021 | E346: 2 | F346: =VLOOKUP(B346,'Facility List'!$B$2:$E$156,3,0) -> Region 6
A347: SIERRA BLANCA LANDFILL | B347: 957A | C347: RN101494409 | D347: 2017 | E347: 4853 | F347: =VLOOKUP(B347,'Facility List'!$B$2:$E$156,3,0) -> Region 6
A348: SIERRA BLANCA LANDFILL | B348: 957A | C348: RN101494409 | D348: 2018 | E348: 4545 | F348: =VLOOKUP(B348,'Facility List'!$B$2:$E$156,3,0) -> Region 6
...

Sheet inc_pop_den
A1: Region | B1: year | C1: Region_Year | D1: rpinc | E1: pop | F1: AREA | G1: rpcpinc | H1: density | I1: Group | O1: 0.33 | P1: 0.66
A2: Region 1 | B2: 2017 | C2: =A2&"_"&B2 -> Region 1_2017 | D2: 21482281 | E2: 436906 | F2: 25753.14 | G2: 49169.113 | H2: 16.965155 | I2: =IF(H2<=$O$3,"Low Den",IF(AND(H2>$O$3,H2<=$P$3),"Mid Den","High Den")) -> Low Den | O2: p33 | P2: p66
A3: Region 1 | B3: 2018 | C3: =A3&"_"&B3 -> Region 1_2018 | D3: 21162455 | E3: 435167 | F3: 25753.14 | G3: 48630.653 | H3: 16.897629 | I3: =IF(H3<=$O$3,"Low Den",IF(AND(H3>$O$3,H3<=$P$3),"Mid Den","High Den")) -> Low Den | O3: =_xlfn.PERCENTILE.EXC($H$2:$H$81,O1) -> 31.518635 | P3: =_xlfn.PERCENTILE.EXC($H$2:$H$81,P1) -> 74.574034
A4: Region 1 | B4: 2019 | C4: =A4&"_"&B4 -> Region 1_2019 | D4: 22129085 | E4: 434349 | F4: 25753.14 | G4: 50947.705 | H4: 16.865866 | I4: =IF(H4<=$O$3,"Low Den",IF(AND(H4>$O$3,H4<=$P$3),"Mid Den","High Den")) -> Low Den
A5: Region 1 | B5: 2020 | C5: =A5&"_"&B5 -> Region 1_2020 | D5: 23268254 | E5: 433919 | F5: 25753.14 | G5: 53623.497 | H5: 16.849169 | I5: =IF(H5<=$O$3,"Low Den",IF(AND(H5>$O$3,H5<=$P$3),"Mid Den","High Den")) -> Low Den
A6: Region 1 | B6: 2021 | C6: =A6&"_"&B6 -> Region 1_2021 | D6: 24078820 | E6: 433971 | F6: 25753.14 | G6: 55484.86 | H6: 16.851188 | I6: =IF(H6<=$O$3,"Low Den",IF(AND(H6>$O$3,H6<=$P$3),"Mid Den","High Den")) -> Low Den
A7: Region 10 | B7: 2017 | C7: =A7&"_"&B7 -> Region 10_2017 | D7: 32988741 | E7: 774777 | F7: 12010.37 | G7: 42578.37 | H7: 64.509003 | I7: =IF(H7<=$O$3,"Low Den",IF(AND(H7>$O$3,H7<=$P$3),"Mid Den","High Den")) -> Mid Den
A8: Region 10 | B8: 2018 | C8: =A8&"_"&B8 -> Region 10_2018 | D8: 33069308 | E8: 769638 | F8: 12010.37 | G8: 42967.354 | H8: 64.081123 | I8: =IF(H8<=$O$3,"Low Den",IF(AND(H8>$O$3,H8<=$P$3),"Mid Den","High Den")) -> Mid Den
A9: Region 10 | B9: 2019 | C9: =A9&"_"&B9 -> Region 10_2019 | D9: 33530789 | E9: 768468 | F9: 12010.37 | G9: 43633.293 | H9: 63.983707 | I9: =IF(H9<=$O$3,"Low Den",IF(AND(H9>$O$3,H9<=$P$3),"Mid Den","High Den")) -> Mid Den
A10: Region 10 | B10: 2020 | C10: =A10&"_"&B10 -> Region 10_2020 | D10: 34809076 | E10: 768192 | F10: 12010.37 | G10: 45312.989 | H10: 63.960727 | I10: =IF(H10<=$O$3,"Low Den",IF(AND(H10>$O$3,H10<=$P$3),"Mid Den","High Den")) -> Mid Den
A11: Region 10 | B11: 2021 | C11: =A11&"_"&B11 -> Region 10_2021 | D11: 35378567 | E11: 769631 | F11: 12010.37 | G11: 45968.22 | H11: 64.08054 | I11: =IF(H11<=$O$3,"Low Den",IF(AND(H11>$O$3,H11<=$P$3),"Mid Den","High Den")) -> Mid Den
A12: Region 11 | B12: 2017 | C12: =A12&"_"&B12 -> Region 11_2017 | D12: 1.3394837e+08 | E12: 2238129 | F12: 8436.46 | G12: 59848.367 | H12: 265.29243 | I12: =IF(H12<=$O$3,"Low Den",IF(AND(H12>$O$3,H12<=$P$3),"Mid Den","High Den")) -> High Den
A13: Region 11 | B13: 2018 | C13: =A13&"_"&B13 -> Region 11_2018 | D13: 1.4202104e+08 | E13: 2290679 | F13: 8436.46 | G13: 61999.536 | H13: 271.52135 | I13: =IF(H13<=$O$3,"Low Den",IF(AND(H13>$O$3,H13<=$P$3),"Mid Den","High Den")) -> High Den
A14: Region 11 | B14: 2019 | C14: =A14&"_"&B14 -> Region 11_2019 | D14: 1.5026032e+08 | E14: 2353618 | F14: 8436.46 | G14: 63842.272 | H14: 278.98171 | I14: =IF(H14<=$O$3,"Low Den",IF(AND(H14>$O$3,H14<=$P$3),"Mid Den","High Den")) -> High Den
A15: Region 11 | B15: 2020 | C15: =A15&"_"&B15 -> Region 11_2020 | D15: 156413779 | E15: 2423206 | F15: 8436.46 | G15: 64548.28 | H15: 287.23019 | I15: =IF(H15<=$O$3,"Low Den",IF(AND(H15>$O$3,H15<=$P$3),"Mid Den","High Den")) -> High Den
... A81: Region 9 | B81: 2021 | C81: =A81&"_"&B81 -> Region 9_2021 | D81: 59052815 | E81: 1274934 | F81: 17110.57 | G81: 46318.331 | H81: 74.511486 | I81: =IF(H81<=$O$3,"Low Den",IF(AND(H81>$O$3,H81<=$P$3),"Mid Den","High Den")) -> Mid Den

Sheet Work Data
A1: Lookup | B1: Region | C1: Year | D1: AgWaste | E1: Population | F1: Group | G1: WastePC | H1: IncomePC | BA1: Group | BB1: WastePC | BC1: IncomePC | BD1: IncomePC^2 | BF1: SUMMARY OUTPUT
A2: =B2&"_"&C2 -> Region 1_2017 | B2: Region 1 | C2: 2017 | D2: 420002.75 | E2: =VLOOKUP($A2,inc_pop_den!$C:$H,3,0) -> 436906 | F2: =VLOOKUP($A2,inc_pop_den!$C:$I,7,0) -> Low Den | G2: =D2/E2 -> 0.96131147 | H2: =VLOOKUP($A2,inc_pop_den!$C:$I,5,0) -> 49169.113 | L2: Descriptive Statistics | AW2: Correl | BA2: =F2 -> Low Den | BB2: =LN(G2) -> -0.03945681 | BC2: =LN(H2) -> 10.803021 | BD2: =BC2^2 -> 116.70526
A3: =B3&"_"&C3 -> Region 1_2018 | B3: Region 1 | C3: 2018 | D3: 423464.18 | E3: =VLOOKUP($A3,inc_pop_den!$C:$H,3,0) -> 435167 | F3: =VLOOKUP($A3,inc_pop_den!$C:$I,7,0) -> Low Den | G3: =D3/E3 -> 0.9731073 | H3: =VLOOKUP($A3,inc_pop_den!$C:$I,5,0) -> 48630.653 | L3: Group | M3: Sample Size | N3: Mean | O3: correlations | AV3: Overall | AW3: =CORREL(BB2:BB81,BC2:BC81) -> 0.27196674 | BA3: =F3 -> Low Den | BB3: =LN(G3) -> -0.027260924 | BC3: =LN(H3) -> 10.792009 | BD3: =BC3^2 -> 116.46747 | BF3: Regression Statistics
A4: =B4&"_"&C4 -> Region 1_2019 | B4: Region 1 | C4: 2019 | D4: 358148.85 | E4: =VLOOKUP($A4,inc_pop_den!$C:$H,3,0) -> 434349 | F4: =VLOOKUP($A4,inc_pop_den!$C:$I,7,0) -> Low Den | G4: =D4/E4 -> 0.82456469 | H4: =VLOOKUP($A4,inc_pop_den!$C:$I,5,0) -> 50947.705 | L4: Overall | M4: =COUNT(G2:G81) -> 80 | N4: =AVERAGE(G2:G81) -> 0.83031657 | O4: =CORREL(G2:G81,H2:H81) -> 0.25862071 | AV4: Low Den | AW4: {=CORREL(IF(BA:BA=AV4,BB:BB),IF(BA:BA=AV4,BC:BC))} -> -0.051808976 | BA4: =F4 -> Low Den | BB4: =LN(G4) -> -0.19289968 | BC4: =LN(H4) -> 10.838555 | BD4: =BC4^2 -> 117.47427 | BF4: Multiple R | BG4: 0.27196674
A5: =B5&"_"&C5 -> Region 1_2020 | B5: Region 1 | C5: 2020 | D5: 360217.45 | E5: =VLOOKUP($A5,inc_pop_den!$C:$H,3,0) -> 433919 | F5: =VLOOKUP($A5,inc_pop_den!$C:$I,7,0) -> Low Den | G5: =D5/E5 -> 0.83014906 | H5: =VLOOKUP($A5,inc_pop_den!$C:$I,5,0) -> 53623.497 | L5: Low Den | M5: {=COUNT(IF(F:F=L5,G:G))} -> 26 | N5: {=AVERAGE(IF(F:F=L5,G:G))} -> 0.93706695 | O5: {=CORREL(IF(F:F=L5,G:G),IF(F:F=L5,H:H))} -> -0.0098867248 | AV5: Mid Den | AW5: {=CORREL(IF(BA:BA=AV5,BB:BB),IF(BA:BA=AV5,BC:BC))} -> 0.70296703 | BA5: =F5 -> Low Den | BB5: =LN(G5) -> -0.18615 | BC5: =LN(H5) -> 10.889743 | BD5: =BC5^2 -> 118.58649 | BF5: R Square | BG5: 0.07396591
A6: =B6&"_"&C6 -> Region 1_2021 | B6: Region 1 | C6: 2021 | D6: 365624.43 | E6: =VLOOKUP($A6,inc_pop_den!$C:$H,3,0) -> 433971 | F6: =VLOOKUP($A6,inc_pop_den!$C:$I,7,0) -> Low Den | G6: =D6/E6 -> 0.8425089 | H6: =VLOOKUP($A6,inc_pop_den!$C:$I,5,0) -> 55484.86 | L6: Mid Den | M6: {=COUNT(IF(F:F=L6,G:G))} -> 27 | N6: {=AVERAGE(IF(F:F=L6,G:G))} -> 0.78892807 | O6: {=CORREL(IF(F:F=L6,G:G),IF(F:F=L6,H:H))} -> 0.63109803 | AV6: High Den | AW6: {=CORREL(IF(BA:BA=AV6,BB:BB),IF(BA:BA=AV6,BC:BC))} -> 0.33889691 | BA6: =F6 -> Low Den | BB6: =LN(G6) -> -0.17137105 | BC6: =LN(H6) -> 10.923865 | BD6: =BC6^2 -> 119.33084 | BF6: Adjusted R Square | BG6: 0.062093678
A7: =B7&"_"&C7 -> Region 10_2017 | B7: Region 10 | C7: 2017 | D7: 704740.63 | E7: =VLOOKUP($A7,inc_pop_den!$C:$H,3,0) -> 774777 | F7: =VLOOKUP($A7,inc_pop_den!$C:$I,7,0) -> Mid Den | G7: =D7/E7 -> 0.90960448 | H7: =VLOOKUP($A7,inc_pop_den!$C:$I,5,0) -> 42578.37 | L7: High Den | M7: {=COUNT(IF(F:F=L7,G:G))} -> 27 | N7: {=AVERAGE(IF(F:F=L7,G:G))} -> 0.76890841 | O7: {=CORREL(IF(F:F=L7,G:G),IF(F:F=L7,H:H))} -> 0.39862264 | BA7: =F7 -> Mid Den | BB7: =LN(G7) -> -0.094745412 | BC7: =LN(H7) -> 10.659102 | BD7: =BC7^2 -> 113.61645 | BF7: Standard Error | BG7: 0.19502076
A8: =B8&"_"&C8 -> Region 10_2018 | B8: Region 10 | C8: 2018 | D8: 845954.7 | E8: =VLOOKUP($A8,inc_pop_den!$C:$H,3,0) -> 769638 | F8: =VLOOKUP($A8,inc_pop_den!$C:$I,7,0) -> Mid Den | G8: =D8/E8 -> 1.0991592 | H8: =VLOOKUP($A8,inc_pop_den!$C:$I,5,0) -> 42967.354 | BA8: =F8 -> Mid Den | BB8: =LN(G8) -> 0.094545538 | BC8: =LN(H8) -> 10.668196 | BD8: =BC8^2 -> 113.8104 | BF8: Observations | BG8: 80
A9: =B9&"_"&C9 -> Region 10_2019 | B9: Region 10 | C9: 2019 | D9: 697386.54 | E9: =VLOOKUP($A9,inc_pop_den!$C:$H,3,0) -> 768468 | F9: =VLOOKUP($A9,inc_pop_den!$C:$I,7,0) -> Mid Den | G9: =D9/E9 -> 0.90750238 | H9: =VLOOKUP($A9,inc_pop_den!$C:$I,5,0) -> 43633.293 | BA9: =F9 -> Mid Den | BB9: =LN(G9) -> -0.097059089 | BC9: =LN(H9) -> 10.683576 | BD9: =BC9^2 -> 114.13879
A10: =B10&"_"&C10 -> Region 10_2020 | B10: Region 10 | C10: 2020 | D10: 764794.1 | E10: =VLOOKUP($A10,inc_pop_den!$C:$H,3,0) -> 768192 | F10: =VLOOKUP($A10,inc_pop_den!$C:$I,7,0) -> Mid Den | G10: =D10/E10 -> 0.99557676 | H10: =VLOOKUP($A10,inc_pop_den!$C:$I,5,0) -> 45312.989 | BA10: =F10 -> Mid Den | BB10: =LN(G10) -> -0.0044330546 | BC10: =LN(H10) -> 10.721349 | BD10: =BC10^2 -> 114.94732 | BF10: ANOVA
A11: =B11&"_"&C11 -> Region 10_2021 | B11: Region 10 | C11: 2021 | D11: 792255.71 | E11: =VLOOKUP($A11,inc_pop_den!$C:$H,3,0) -> 769631 | F11: =VLOOKUP($A11,inc_pop_den!$C:$I,7,0) -> Mid Den | G11: =D11/E11 -> 1.0293968 | H11: =VLOOKUP($A11,inc_pop_den!$C:$I,5,0) -> 45968.22 | BA11: =F11 -> Mid Den | BB11: =LN(G11) -> 0.028973027 | BC11: =LN(H11) -> 10.735706 | BD11: =BC11^2 -> 115.25537 | BG11: df | BH11: SS | BI11: MS | BJ11: F | BK11: Significance F
A12: =B12&"_"&C12 -> Region 11_2017 | B12: Region 11 | C12: 2017 | D12: 1842281.4 | E12: =VLOOKUP($A12,inc_pop_den!$C:$H,3,0) -> 2238129 | F12: =VLOOKUP($A12,inc_pop_den!$C:$I,7,0) -> High Den | G12: =D12/E12 -> 0.82313457 | H12: =VLOOKUP($A12,inc_pop_den!$C:$I,5,0) -> 59848.367 | BA12: =F12 -> High Den | BB12: =LN(G12) -> -0.19463558 | BC12: =LN(H12) -> 10.999569 | BD12: =BC12^2 -> 120.99053 | BF12: Regression | BG12: 1 | BH12: 0.23695229 | BI12: 0.23695229 | BJ12: 6.2301604 | BK12: 0.014668963
A13: =B13&"_"&C13 -> Region 11_2018 | B13: Region 11 | C13: 2018 | D13: 1847787.1 | E13: =VLOOKUP($A13,inc_pop_den!$C:$H,3,0) -> 2290679 | F13: =VLOOKUP($A13,inc_pop_den!$C:$I,7,0) -> High Den | G13: =D13/E13 -> 0.80665475 | H13: =VLOOKUP($A13,inc_pop_den!$C:$I,5,0) -> 61999.536 | BA13: =F13 -> High Den | BB13: =LN(G13) -> -0.21485952 | BC13: =LN(H13) -> 11.034882 | BD13: =BC13^2 -> 121.76862 | BF13: Residual | BG13: 78 | BH13: 2.9665815 | BI13: 0.038033096
A14: =B14&"_"&C14 -> Region 11_2019 | B14: Region 11 | C14: 2019 | D14: 1911827.2 | E14: =VLOOKUP($A14,inc_pop_den!$C:$H,3,0) -> 2353618 | F14: =VLOOKUP($A14,inc_pop_den!$C:$I,7,0) -> High Den | G14: =D14/E14 -> 0.81229289 | H14: =VLOOKUP($A14,inc_pop_den!$C:$I,5,0) -> 63842.272 | BA14: =F14 -> High Den | BB14: =LN(G14) -> -0.20789431 | BC14: =LN(H14) -> 11.064171 | BD14: =BC14^2 -> 122.41588 | BF14: Total | BG14: 79 | BH14: 3.2035338
A15: =B15&"_"&C15 -> Region 11_2020 | B15: Region 11 | C15: 2020 | D15: 1979558.3 | E15: =VLOOKUP($A15,inc_pop_den!$C:$H,3,0) -> 2423206 | F15: =VLOOKUP($A15,inc_pop_den!$C:$I,7,0) -> High Den | G15: =D15/E15 -> 0.81691703 | H15: =VLOOKUP($A15,inc_pop_den!$C:$I,5,0) -> 64548.28 | BA15: =F15 -> High Den | BB15: =LN(G15) -> -0.20221774 | BC15: =LN(H15) -> 11.075169 | BD15: =BC15^2 -> 122.65936
A16: =B16&"_"&C16 -> Region 11_2021 | B16: Region 11 | C16: 2021 | D16: 2222878.4 | E16: =VLOOKUP($A16,inc_pop_den!$C:$H,3,0) -> 2479637 | F16: =VLOOKUP($A16,inc_pop_den!$C:$I,7,0) -> High Den | G16: =D16/E16 -> 0.89645316 | H16: =VLOOKUP($A16,inc_pop_den!$C:$I,5,0) -> 67653.011 | BA16: =F16 -> High Den | BB16: =LN(G16) -> -0.10930923 | BC16: =LN(H16) -> 11.122147 | BD16: =BC16^2 -> 123.70216 | BG16: Coefficients | BH16: Standard Error | BI16: t Stat | BJ16: P-value | BK16: Lower 95% | BL16: Upper 95% | BM16: Lower 95.0% | BN16: Upper 95.0%
A17: =B17&"_"&C17 -> Region 12_2017 | B17: Region 12 | C17: 2017 | D17: 5254267 | E17: =VLOOKUP($A17,inc_pop_den!$C:$H,3,0) -> 7062795 | F17: =VLOOKUP($A17,inc_pop_den!$C:$I,7,0) -> High Den | G17: =D17/E17 -> 0.74393593 | H17: =VLOOKUP($A17,inc_pop_den!$C:$I,5,0) -> 57455.652 | BA17: =F17 -> High Den | BB17: =LN(G17) -> -0.29580036 | BC17: =LN(H17) -> 10.958769 | BD17: =BC17^2 -> 120.09461 | BF17: Intercept | BG17: -2.8375337 | BH17: 1.0551345 | BI17: -2.6892626 | BJ17: 0.0087538425 | BK17: -4.9381452 | BL17: -0.7369223 | BM17: -4.9381452 | BN17: -0.7369223
A18: =B18&"_"&C18 -> Region 12_2018 | B18: Region 12 | C18: 2018 | D18: 5726100.9 | E18: =VLOOKUP($A18,inc_pop_den!$C:$H,3,0) -> 7136903 | F18: =VLOOKUP($A18,inc_pop_den!$C:$I,7,0) -> High Den | G18: =D18/E18 -> 0.80232293 | H18: =VLOOKUP($A18,inc_pop_den!$C:$I,5,0) -> 59243.148 | BA18: =F18 -> High Den | BB18: =LN(G18) -> -0.22024409 | BC18: =LN(H18) -> 10.989405 | BD18: =BC18^2 -> 120.76703 | BF18: IncomePC | BG18: 0.24405729 | BH18: 0.097778228 | BI18: 2.4960289 | BJ18: 0.014668963 | BK18: 0.049395787 | BL18: 0.43871878 | BM18: 0.049395787 | BN18: 0.43871878
A19: =B19&"_"&C19 -> Region 12_2019 | B19: Region 12 | C19: 2019 | D19: 5116993.9 | E19: =VLOOKUP($A19,inc_pop_den!$C:$H,3,0) -> 7222524 | F19: =VLOOKUP($A19,inc_pop_den!$C:$I,7,0) -> High Den | G19: =D19/E19 -> 0.70847724 | H19: =VLOOKUP($A19,inc_pop_den!$C:$I,5,0) -> 60420.583 | BA19: =F19 -> High Den | BB19: =LN(G19) -> -0.34463734 | BC19: =LN(H19) -> 11.009085 | BD19: =BC19^2 -> 121.19995
A20: =B20&"_"&C20 -> Region 12_2020 | B20: Region 12 | C20: 2020 | D20: 4857113.2 | E20: =VLOOKUP($A20,inc_pop_den!$C:$H,3,0) -> 7312675 | F20: =VLOOKUP($A20,inc_pop_den!$C:$I,7,0) -> High Den | G20: =D20/E20 -> 0.66420472 | H20: =VLOOKUP($A20,inc_pop_den!$C:$I,5,0) -> 60665.397 | BA20: =F20 -> High Den | BB20: =LN(G20) -> -0.40916486 | BC20: =LN(H20) -> 11.013129 | BD20: =BC20^2 -> 121.289
A21: =B21&"_"&C21 -> Region 12_2021 | B21: Region 12 | C21: 2021 | D21: 4996293.6 | E21: =VLOOKUP($A21,inc_pop_den!$C:$H,3,0) -> 7383513 | F21: =VLOOKUP($A21,inc_pop_den!$C:$I,7,0) -> High Den | G21: =D21/E21 -> 0.67668244 | H21: =VLOOKUP($A21,inc_pop_den!$C:$I,5,0) -> 61464.366 | BA21: =F21 -> High Den | BB21: =LN(G21) -> -0.39055319 | BC21: =LN(H21) -> 11.026213 | BD21: =BC21^2 -> 121.57737
A22: =B22&"_"&C22 -> Region 13_2017 | B22: Region 13 | C22: 2017 | D22: 1539283.6 | E22: =VLOOKUP($A22,inc_pop_den!$C:$H,3,0) -> 2596968 | F22: =VLOOKUP($A22,inc_pop_den!$C:$I,7,0) -> High Den | G22: =D22/E22 -> 0.59272337 | H22: =VLOOKUP($A22,inc_pop_den!$C:$I,5,0) -> 48906.146 | BA22: =F22 -> High Den | BB22: =LN(G22) -> -0.52302748 | BC22: =LN(H22) -> 10.797658 | BD22: =BC22^2 -> 116.58943
A23: =B23&"_"&C23 -> Region 13_2018 | B23: Region 13 | C23: 2018 | D23: 1543641.1 | E23: =VLOOKUP($A23,inc_pop_den!$C:$H,3,0) -> 2635506 | F23: =VLOOKUP($A23,inc_pop_den!$C:$I,7,0) -> High Den | G23: =D23/E23 -> 0.58570958 | H23: =VLOOKUP($A23,inc_pop_den!$C:$I,5,0) -> 50140.165 | BA23: =F23 -> High Den | BB23: =LN(G23) -> -0.53493122 | BC23: =LN(H23) -> 10.822578 | BD23: =BC23^2 -> 117.12819
A24: =B24&"_"&C24 -> Region 13_2019 | B24: Region 13 | C24: 2019 | D24: 1599954.2 | E24: =VLOOKUP($A24,inc_pop_den!$C:$H,3,0) -> 2669813 | F24: =VLOOKUP($A24,inc_pop_den!$C:$I,7,0) -> High Den | G24: =D24/E24 -> 0.59927575 | H24: =VLOOKUP($A24,inc_pop_den!$C:$I,5,0) -> 49702.804 | BA24: =F24 -> High Den | BB24: =LN(G24) -> -0.51203344 | BC24: =LN(H24) -> 10.813817 | BD24: =BC24^2 -> 116.93863
A25: =B25&"_"&C25 -> Region 13_2020 | B25: Region 13 | C25: 2020 | D25: 1614969.3 | E25: =VLOOKUP($A25,inc_pop_den!$C:$H,3,0) -> 2707875 | F25: =VLOOKUP($A25,inc_pop_den!$C:$I,7,0) -> High Den | G25: =D25/E25 -> 0.59639727 | H25: =VLOOKUP($A25,inc_pop_den!$C:$I,5,0) -> 50558.07 | BA25: =F25 -> High Den | BB25: =LN(G25) -> -0.51684827 | BC25: =LN(H25) -> 10.830878 | BD25: =BC25^2 -> 117.30792
A26: =B26&"_"&C26 -> Region 13_2021 | B26: Region 13 | C26: 2021 | D26: 1729898.2 | E26: =VLOOKUP($A26,inc_pop_den!$C:$H,3,0) -> 2744429 | F26: =VLOOKUP($A26,inc_pop_den!$C:$I,7,0) -> High Den | G26: =D26/E26 -> 0.63033084 | H26: =VLOOKUP($A26,inc_pop_den!$C:$I,5,0) -> 51635.958 | BA26: =F26 -> High Den | BB26: =LN(G26) -> -0.46151045 | BC26: =LN(H26) -> 10.851974 | BD26: =BC26^2 -> 117.76533
A27: =B27&"_"&C27 -> Region 14_2017 | B27: Region 14 | C27: 2017 | D27: 570895.12 | E27: =VLOOKUP($A27,inc_pop_den!$C:$H,3,0) -> 763576 | F27: =VLOOKUP($A27,inc_pop_den!$C:$I,7,0) -> Mid Den | G27: =D27/E27 -> 0.74765985 | H27: =VLOOKUP($A27,inc_pop_den!$C:$I,5,0) -> 45394.973 | BA27: =F27 -> Mid Den | BB27: =LN(G27) -> -0.29080715 | BC27: =LN(H27) -> 10.723157 | BD27: =BC27^2 -> 114.98609
A28: =B28&"_"&C28 -> Region 14_2018 | B28: Region 14 | C28: 2018 | D28: 714875.94 | E28: =VLOOKUP($A28,inc_pop_den!$C:$H,3,0) -> 759118 | F28: =VLOOKUP($A28,inc_pop_den!$C:$I,7,0) -> Mid Den | G28: =D28/E28 -> 0.94171913 | H28: =VLOOKUP($A28,inc_pop_den!$C:$I,5,0) -> 46308.538 | BA28: =F28 -> Mid Den | BB28: =LN(G28) -> -0.060048216 | BC28: =LN(H28) -> 10.743082 | BD28: =BC28^2 -> 115.4138
A29: =B29&"_"&C29 -> Region 14_2019 | B29: Region 14 | C29: 2019 | D29: 629510.93 | E29: =VLOOKUP($A29,inc_pop_den!$C:$H,3,0) -> 757823 | F29: =VLOOKUP($A29,inc_pop_den!$C:$I,7,0) -> Mid Den | G29: =D29/E29 -> 0.83068333 | H29: =VLOOKUP($A29,inc_pop_den!$C:$I,5,0) -> 48422.439 | BA29: =F29 -> Mid Den | BB29: =LN(G29) -> -0.18550663 | BC29: =LN(H29) -> 10.787719 | BD29: =BC29^2 -> 116.37487
A30: =B30&"_"&C30 -> Region 14_2020 | B30: Region 14 | C30: 2020 | D30: 620433.14 | E30: =VLOOKUP($A30,inc_pop_den!$C:$H,3,0) -> 757717 | F30: =VLOOKUP($A30,inc_pop_den!$C:$I,7,0) -> Mid Den | G30: =D30/E30 -> 0.81881908 | H30: =VLOOKUP($A30,inc_pop_den!$C:$I,5,0) -> 49493.721 | BA30: =F30 -> Mid Den | BB30: =LN(G30) -> -0.19989212 | BC30: =LN(H30) -> 10.809601 | BD30: =BC30^2 -> 116.84748
... A81: =B81&"_"&C81 -> Region 9_2021 | B81: Region 9 | C81: 2021 | D81: 1228549.5 | E81: =VLOOKUP($A81,inc_pop_den!$C:$H,3,0) -> 1274934 | F81: =VLOOKUP($A81,inc_pop_den!$C:$I,7,0) -> Mid Den | G81: =D81/E81 -> 0.9636181 | H81: =VLOOKUP($A81,inc_pop_den!$C:$I,5,0) -> 46318.331 | BA81: =F81 -> Mid Den | BB81: =LN(G81) -> -0.037060224 | BC81: =LN(H81) -> 10.743293 | BD81: =BC81^2 -> 115.41835

Sheet Descriptive Statistics
A1: Group | B1: WastePC | C1: IncomePC
A2: Low Den | B2: 0.96131147 | C2: 49169.113 | F2: Descriptive Statistics for Waste per Capita
A3: Low Den | B3: 0.9731073 | C3: 48630.653
A4: Low Den | B4: 0.82456469 | C4: 50947.705 | F4: Group | G4: Sample Size | H4: Minimum | I4: Mean | J4: Median | K4: Max | L4: Std. Deviation | M4: Correlation | N4: Log Correlation
A5: Low Den | B5: 0.83014906 | C5: 53623.497 | F5: Overall | G5: =COUNT($B2:B81) -> 80 | H5: =MIN($B$2:$B$81) -> 0.44641572 | I5: =AVERAGE(B2:B81) -> 0.83031657 | J5: =MEDIAN(B2:B81) -> 0.84365437 | K5: =MAX(B2:B81) -> 1.0991592 | L5: =_xlfn.STDEV.S(B2:B81) -> 0.14962115 | M5: =CORREL(B2:B81,C2:C81) -> 0.25862071 | N5: 0.27196674
A6: Low Den | B6: 0.8425089 | C6: 55484.86 | F6: Low Den | G6: {=COUNT(IF($A:$A=$F6,$B:$B))} -> 26 | H6: {=MIN(IF($A:$A=$F6,$B:$B))} -> 0.82456469 | I6: {=AVERAGE(IF($A:$A=$F6,$B:$B))} -> 0.93706695 | J6: {=MEDIAN(IF($A:$A=$F6,$B:$B))} -> 0.95148474 | K6: {=MAX(IF($A:$A=$F6,$B:$B))} -> 1.0458094 | L6: {=_xlfn.STDEV.S(IF($A:$A=$F6,$B:$B))} -> 0.065703989 | M6: {=CORREL(IF($A:$A=F6,B:B),IF(A:A=F6,C:C))} -> -0.0098867248 | N6: -0.051808976
A7: Mid Den | B7: 0.90960448 | C7: 42578.37 | F7: Mid Den | G7: {=COUNT(IF($A:$A=$F7,$B:$B))} -> 27 | H7: {=MIN(IF($A:$A=$F7,$B:$B))} -> 0.44641572 | I7: {=AVERAGE(IF($A:$A=$F7,$B:$B))} -> 0.78892807 | J7: {=MEDIAN(IF($A:$A=$F7,$B:$B))} -> 0.83068333 | K7: {=MAX(IF($A:$A=$F7,$B:$B))} -> 1.0991592 | L7: {=_xlfn.STDEV.S(IF($A:$A=$F7,$B:$B))} -> 0.17734511 | M7: {=CORREL(IF($A:$A=F7,B:B),IF(A:A=F7,C:C))} -> 0.63109803 | N7: 0.70296703
A8: Mid Den | B8: 1.0991592 | C8: 42967.354 | F8: High Den | G8: {=COUNT(IF($A:$A=$F8,$B:$B))} -> 27 | H8: {=MIN(IF($A:$A=$F8,$B:$B))} -> 0.58570958 | I8: {=AVERAGE(IF($A:$A=$F8,$B:$B))} -> 0.76890841 | J8: {=MEDIAN(IF($A:$A=$F8,$B:$B))} -> 0.75189779 | K8: {=MAX(IF($A:$A=$F8,$B:$B))} -> 0.99087828 | L8: {=_xlfn.STDEV.S(IF($A:$A=$F8,$B:$B))} -> 0.12380504 | M8: {=CORREL(IF($A:$A=F8,B:B),IF(A:A=F8,C:C))} -> 0.39862264 | N8: 0.33889691
A9: Mid Den | B9: 0.90750238 | C9: 43633.293
A10: Mid Den | B10: 0.99557676 | C10: 45312.989
A11: Mid Den | B11: 1.0293968 | C11: 45968.22 | F11: Confidence Intervals for the Mean | O11: Alpha/2 | P11: 0.05 | Q11: 0.025 | R11: 0.005
A12: High Den | B12: 0.82313457 | C12: 59848.367 | F12: Group | G12: Mean | H12: LCL-90 | I12: LCL-95 | J12: LCL-99 | K12: UCL-90 | L12: UCL-95 | M12: UCL-99 | P12: 90% ME | Q12: 95% ME | R12: 99% ME | T12: Std. Dev | U12: Count | V12: n(a/2,n-1)
A13: High Den | B13: 0.80665475 | C13: 61999.536 | F13: Overall | G13: 0.83031657 | H13: =$G13-P13 -> 0.80247471 | I13: =$G13-Q13 -> 0.79702001 | J13: =$G13-R13 -> 0.78616253 | K13: =$G13+P13 -> 0.85815843 | L13: =$G13+Q13 -> 0.86361313 | M13: =$G13+R13 -> 0.87447061 | O13: Overall | P13: =($T13/SQRT($U13))*V13 -> 0.02784186 | Q13: =($T13/SQRT($U13))*W13 -> 0.033296556 | R13: =($T13/SQRT($U13))*X13 -> 0.044154038 | T13: =L5 -> 0.14962115 | U13: =G5 -> 80 | V13: =_xlfn.T.INV(1-P$11,$U13-1) -> 1.6643714 | W13: =_xlfn.T.INV(1-Q$11,$U13-1) -> 1.9904502 | X13: =_xlfn.T.INV(1-R$11,$U13-1) -> 2.6395046
A14: High Den | B14: 0.81229289 | C14: 63842.272 | F14: Low Den | G14: 0.93706695 | H14: =$G14-P14 -> 0.91505651 | I14: =$G14-Q14 -> 0.91052853 | J14: =$G14-R14 -> 0.90114913 | K14: =$G14+P14 -> 0.95907739 | L14: =$G14+Q14 -> 0.96360536 | M14: =$G14+R14 -> 0.97298476 | O14: High | P14: =($T14/SQRT($U14))*V14 -> 0.02201044 | Q14: =($T14/SQRT($U14))*W14 -> 0.026538415 | R14: =($T14/SQRT($U14))*X14 -> 0.035917817 | T14: =L6 -> 0.065703989 | U14: =G6 -> 26 | V14: =_xlfn.T.INV(1-P$11,$U14-1) -> 1.7081408 | W14: =_xlfn.T.INV(1-Q$11,$U14-1) -> 2.0595386 | X14: =_xlfn.T.INV(1-R$11,$U14-1) -> 2.7874358
A15: High Den | B15: 0.81691703 | C15: 64548.28 | F15: Mid Den | G15: 0.78892807 | H15: =$G15-P15 -> 0.73071519 | I15: =$G15-Q15 -> 0.71877268 | J15: =$G15-R15 -> 0.69409032 | K15: =$G15+P15 -> 0.84714095 | L15: =$G15+Q15 -> 0.85908346 | M15: =$G15+R15 -> 0.88376583 | O15: Mid | P15: =($T15/SQRT($U15))*V15 -> 0.058212881 | Q15: =($T15/SQRT($U15))*W15 -> 0.07015539 | R15: =($T15/SQRT($U15))*X15 -> 0.094837757 | T15: =L7 -> 0.17734511 | U15: =G7 -> 27 | V15: =_xlfn.T.INV(1-P$11,$U15-1) -> 1.7056179 | W15: =_xlfn.T.INV(1-Q$11,$U15-1) -> 2.0555294 | X15: =_xlfn.T.INV(1-R$11,$U15-1) -> 2.7787145
A16: High Den | B16: 0.89645316 | C16: 67653.011 | F16: High Den | G16: 0.76890841 | H16: =$G16-P16 -> 0.72826986 | I16: =$G16-Q16 -> 0.71993277 | J16: =$G16-R16 -> 0.70270195 | K16: =$G16+P16 -> 0.80954696 | L16: =$G16+Q16 -> 0.81788405 | M16: =$G16+R16 -> 0.83511487 | O16: Low | P16: =($T16/SQRT($U16))*V16 -> 0.040638548 | Q16: =($T16/SQRT($U16))*W16 -> 0.048975642 | R16: =($T16/SQRT($U16))*X16 -> 0.06620646 | T16: =L8 -> 0.12380504 | U16: =G8 -> 27 | V16: =_xlfn.T.INV(1-P$11,$U16-1) -> 1.7056179 | W16: =_xlfn.T.INV(1-Q$11,$U16-1) -> 2.0555294 | X16: =_xlfn.T.INV(1-R$11,$U16-1) -> 2.7787145
A17: High Den | B17: 0.74393593 | C17: 57455.652
A18: High Den | B18: 0.80232293 | C18: 59243.148
A19: High Den | B19: 0.70847724 | C19: 60420.583
A20: High Den | B20: 0.66420472 | C20: 60665.397
A21: High Den | B21: 0.67668244 | C21: 61464.366
A22: High Den | B22: 0.59272337 | C22: 48906.146
A23: High Den | B23: 0.58570958 | C23: 50140.165
A24: High Den | B24: 0.59927575 | C24: 49702.804
A25: High Den | B25: 0.59639727 | C25: 50558.07
A26: High Den | B26: 0.63033084 | C26: 51635.958
A27: Mid Den | B27: 0.74765985 | C27: 45394.973
A28: Mid Den | B28: 0.94171913 | C28: 46308.538
... A32: High Den | B32: 0.68967624 | C32: 28162.493
A33: High Den | B33: 0.70525719 | C33: 28600.627 | O33: 1-Alpha/2 | R33: Alpha/2
A34: High Den | B34: 0.72710286 | C34: 29307.706 | F34: Confidence Intervals for the Variance | O34: 0.95 | P34: 0.975 | Q34: 0.995 | R34: 0.05 | S34: 0.025 | T34: 0.005
A35: High Den | B35: 0.71683258 | C35: 32266.419 | O35: 90%ChiU | P35: 95%ChiU | Q35: 99%ChiU | R35: 90%ChiL | S35: 95%ChiL | T35: 99%ChiL | V35: Count
A36: High Den | B36: 0.81821054 | C36: 34062.014 | F36: Group | G36: Sample Variance | H36: LCL-90 | I36: LCL-95 | J36: LCL-99 | K36: UCL-90 | L36: UCL-95 | M36: UCL-99 | O36: =_xlfn.CHISQ.INV(O$34,$V36-1) -> 100.74862 | P36: =_xlfn.CHISQ.INV(P$34,$V36-1) -> 105.47275 | Q36: =_xlfn.CHISQ.INV(Q$34,$V36-1) -> 115.11661 | R36: =_xlfn.CHISQ.INV(R$34,$V36-1) -> 59.522294 | S36: =_xlfn.CHISQ.INV(S$34,$V36-1) -> 56.308903 | T36: =_xlfn.CHISQ.INV(T$34,$V36-1) -> 50.376116 | V36: 80
A37: Low Den | B37: 0.95078038 | C37: 33898.355 | F37: Overall | G37: =$L5^2 -> 0.022386489 | H37: =$G37*($V36-1)/O36 -> 0.017553914 | I37: =$G37*($V36-1)/P36 -> 0.016767673 | J37: =$G37*($V36-1)/Q36 -> 0.015362966 | K37: =$G37*($V36-1)/R36 -> 0.029712105 | L37: =$G37*($V36-1)/S36 -> 0.031407691 | M37: =$G37*($V36-1)/T36 -> 0.03510657 | O37: =_xlfn.CHISQ.INV(O$34,$V37-1) -> 37.652484 | P37: =_xlfn.CHISQ.INV(P$34,$V37-1) -> 40.646469 | Q37: =_xlfn.CHISQ.INV(Q$34,$V37-1) -> 46.92789 | R37: =_xlfn.CHISQ.INV(R$34,$V37-1) -> 14.611408 | S37: =_xlfn.CHISQ.INV(S$34,$V37-1) -> 13.11972 | T37: =_xlfn.CHISQ.INV(T$34,$V37-1) -> 10.519652 | V37: 26
A38: Low Den | B38: 0.92043994 | C38: 34766.122 | F38: Low Den | G38: =$L6^2 -> 0.0043170141 | H38: =$G38*($V37-1)/O37 -> 0.0028663541 | I38: =$G38*($V37-1)/P37 -> 0.0026552209 | J38: =$G38*($V37-1)/Q37 -> 0.0022998126 | K38: =$G38*($V37-1)/R37 -> 0.0073863762 | L38: =$G38*($V37-1)/S37 -> 0.0082261933 | M38: =$G38*($V37-1)/T37 -> 0.010259403 | O38: =_xlfn.CHISQ.INV(O$34,$V38-1) -> 38.885139 | P38: =_xlfn.CHISQ.INV(P$34,$V38-1) -> 41.92317 | Q38: =_xlfn.CHISQ.INV(Q$34,$V38-1) -> 48.289882 | R38: =_xlfn.CHISQ.INV(R$34,$V38-1) -> 15.379157 | S38: =_xlfn.CHISQ.INV(S$34,$V38-1) -> 13.843905 | T38: =_xlfn.CHISQ.INV(T$34,$V38-1) -> 11.160237 | V38: 27
A39: Low Den | B39: 0.97351588 | C39: 36137.147 | F39: Mid Den | G39: =$L7^2 -> 0.031451289 | H39: =$G39*($V38-1)/O38 -> 0.021029461 | I39: =$G39*($V38-1)/P38 -> 0.019505527 | J39: =$G39*($V38-1)/Q38 -> 0.016933848 | K39: =$G39*($V38-1)/R38 -> 0.053171545 | L39: =$G39*($V38-1)/S38 -> 0.059068125 | M39: =$G39*($V38-1)/T38 -> 0.073272054 | O39: =_xlfn.CHISQ.INV(O$34,$V39-1) -> 38.885139 | P39: =_xlfn.CHISQ.INV(P$34,$V39-1) -> 41.92317 | Q39: =_xlfn.CHISQ.INV(Q$34,$V39-1) -> 48.289882 | R39: =_xlfn.CHISQ.INV(R$34,$V39-1) -> 15.379157 | S39: =_xlfn.CHISQ.INV(S$34,$V39-1) -> 13.843905 | T39: =_xlfn.CHISQ.INV(T$34,$V39-1) -> 11.160237 | V39: 27
A40: Low Den | B40: 0.97000635 | C40: 38154.285 | F40: High Den | G40: =$L8^2 -> 0.015327687 | H40: =$G40*($V39-1)/O39 -> 0.010248642 | I40: =$G40*($V39-1)/P39 -> 0.0095059574 | J40: =$G40*($V39-1)/Q39 -> 0.0082526577 | K40: =$G40*($V39-1)/R39 -> 0.025912986 | L40: =$G40*($V39-1)/S39 -> 0.028786666 | M40: =$G40*($V39-1)/T39 -> 0.035708906
A41: Low Den | B41: 1.0333881 | C41: 39961.976
A42: Low Den | B42: 0.82697733 | C42: 42781.479
A43: Mid Den | B43: 0.81321442 | C43: 43631.083
...

Sheet For print
B3: Descriptive Statistics for Waste per Capita
B5: Group | C5: Sample Size | D5: Minimum | E5: Mean | F5: Median | G5: Max | H5: Std. Deviation | I5: Correlation | J5: Log Correlation
B6: Overall | C6: 80 | D6: 0.44641572 | E6: 0.83031657 | F6: 0.84365437 | G6: 1.0991592 | H6: 0.14962115 | I6: 0.25862071 | J6: 0.27196674
B7: Low Density | C7: 26 | D7: 0.82456469 | E7: 0.93706695 | F7: 0.95148474 | G7: 1.0458094 | H7: 0.065703989 | I7: -0.0098867248 | J7: -0.051808976
B8: Mid Density | C8: 27 | D8: 0.44641572 | E8: 0.78892807 | F8: 0.83068333 | G8: 1.0991592 | H8: 0.17734511 | I8: 0.63109803 | J8: 0.70296703
B9: High Density | C9: 27 | D9: 0.58570958 | E9: 0.76890841 | F9: 0.75189779 | G9: 0.99087828 | H9: 0.12380504 | I9: 0.39862264 | J9: 0.33889691
B11: Confidence Intervals for the Variance
B13: Group | C13: Sample Variance | D13: LCL-90 | E13: LCL-95 | F13: LCL-99 | G13: UCL-90 | H13: UCL-95 | I13: UCL-99
B14: Overall | C14: 0.022386489 | D14: 0.017553914 | E14: 0.016767673 | F14: 0.015362966 | G14: 0.029712105 | H14: 0.031407691 | I14: 0.03510657
B15: Low Density | C15: 0.0043170141 | D15: 0.0028663541 | E15: 0.0026552209 | F15: 0.0022998126 | G15: 0.0073863762 | H15: 0.0082261933 | I15: 0.010259403
B16: Mid Density | C16: 0.031451289 | D16: 0.021029461 | E16: 0.019505527 | F16: 0.016933848 | G16: 0.053171545 | H16: 0.059068125 | I16: 0.073272054
B17: High Density | C17: 0.015327687 | D17: 0.010248642 | E17: 0.0095059574 | F17: 0.0082526577 | G17: 0.025912986 | H17: 0.028786666 | I17: 0.035708906
B19: Single Sample Hypothesis Tests for Means: Two Tailed Tests
B21: Group | C21: Mean | D21: t-stat | E21: t-Crit 90 | F21: Concl 90 | G21: t-crit 95 | H21: concl 95 | I21: t-Crit 99 | J21: Concl 99
B22: Low | C22: 0.93706695 | D22: 8.2844627 | E22: 1.7081408 | F22: Reject | G22: 2.0595386 | H22: Reject | I22: 2.7874358 | J22: Reject
B23: Mid | C23: 0.78892807 | D23: -1.2126691 | E23: 1.7056179 | F23: F.T.R. | G23: 2.0555294 | H23: F.T.R. | I23: 2.7787145 | J23: F.T.R.
B24: High | C24: 0.76890841 | D24: -2.5773278 | E24: 1.7056179 | F24: Reject | G24: 2.0555294 | H24: Reject | I24: 2.7787145 | J24: F.T.R.
B26: Singl Sample Hypothesis Tests for Variances, Two Tailed Tests
B28: Group | C28: Variance | D28: Chi-Stat | E28: Chi-L 90 | F28: Chi-U 90 | G28: Concl 90 | H28: Chi-L 95 | I28: Chi-U 95 | J28: Concl 95 | K28: Chi-L 99 | L28: Chi-U 99 | M28: Concl 99
B29: Low | C29: 0.0043170141 | D29: 4.821004 | E29: 14.611408 | F29: 37.652484 | G29: Reject | H29: 13.11972 | I29: 40.646469 | J29: Reject | K29: 10.519652 | L29: 46.92789 | M29: Reject
B30: Mid | C30: 0.031451289 | D30: 36.527993 | E30: 15.379157 | F30: 38.885139 | G30: F.T.R. | H30: 13.843905 | I30: 41.92317 | J30: F.T.R. | K30: 11.160237 | L30: 48.289882 | M30: F.T.R
B31: High | C31: 0.015327687 | D31: 17.801803 | E31: 15.379157 | F31: 38.885139 | G31: F.T.R. | H31: 13.843905 | I31: 41.92317 | J31: F.T.R. | K31: 11.160237 | L31: 48.289882 | M31: F.T.R
B34: Confidence Intervals for the Mean
B36: Group | C36: Mean | D36: LCL-90 | E36: LCL-95 | F36: LCL-99 | G36: UCL-90 | H36: UCL-95 | I36: UCL-99
B37: Overall | C37: 0.83031657 | D37: 0.80247471 | E37: 0.79702001 | F37: 0.78616253 | G37: 0.85815843 | H37: 0.86361313 | I37: 0.87447061
B38: Low Den | C38: 0.93706695 | D38: 0.91505651 | E38: 0.91052853 | F38: 0.90114913 | G38: 0.95907739 | H38: 0.96360536 | I38: 0.97298476
B39: Mid Den | C39: 0.78892807 | D39: 0.73071519 | E39: 0.71877268 | F39: 0.69409032 | G39: 0.84714095 | H39: 0.85908346 | I39: 0.88376583
B40: High Den | C40: 0.76890841 | D40: 0.72826986 | E40: 0.71993277 | F40: 0.70270195 | G40: 0.80954696 | H40: 0.81788405 | I40: 0.83511487

Sheet BW Data
B1: Low Density | C1: Mid Density | D1: High Density
B2: 0.96131147 | C2: 0.90960448 | D2: 0.82313457
B3: 0.9731073 | C3: 1.0991592 | D3: 0.80665475
B4: 0.82456469 | C4: 0.90750238 | D4: 0.81229289
B5: 0.83014906 | C5: 0.99557676 | D5: 0.81691703
B6: 0.8425089 | C6: 1.0293968 | D6: 0.89645316
B7: 0.95078038 | C7: 0.74765985 | D7: 0.74393593
B8: 0.92043994 | C8: 0.94171913 | D8: 0.80232293
B9: 0.97351588 | C9: 0.83068333 | D9: 0.70847724
B10: 0.97000635 | C10: 0.81881908 | D10: 0.66420472
B11: 1.0333881 | C11: 0.85124913 | D11: 0.67668244
B12: 0.82697733 | C12: 0.81321442 | D12: 0.59272337
B13: 0.91691534 | C13: 0.8518742 | D13: 0.58570958
... B27: 0.95932334 | C27: 0.85454799 | D27: 0.75189779
C28: 0.9636181 | D28: 0.78440255

Sheet Pivot
A1: Group | B1: Low Den
A3: Row Labels | B3: Count of IncomePC
A4: 0.775-0.85 | B4: 5
A5: 0.85-0.925 | B5: 4
A6: 0.925-1 | B6: 14
A7: 1-1.075 | B7: 3
A8: Grand Total | B8: 26
D14: High | G14: Mid | J14: Low
A15: Class | B15: Overall | D15: Class | E15: Overall | G15: Class | H15: Overall | J15: Class | K15: Overall
A16: 0.4-0.475 | B16: 3 | D16: 0.4-0.475 | E16: 0 | G16: 0.4-0.475 | H16: 3 | J16: 0.4-0.475 | K16: 0
A17: 0.475-0.55 | B17: 2 | D17: 0.475-0.55 | E17: 0 | G17: 0.475-0.55 | H17: 2 | J17: 0.475-0.55 | K17: 0
A18: 0.55-0.625 | B18: 4 | D18: 0.55-0.625 | E18: 4 | G18: 0.55-0.625 | H18: 0 | J18: 0.55-0.625 | K18: 0
A19: 0.625-0.7 | B19: 6 | D19: 0.625-0.7 | E19: 4 | G19: 0.625-0.7 | H19: 2 | J19: 0.625-0.7 | K19: 0
A20: 0.7-0.775 | B20: 8 | D20: 0.7-0.775 | E20: 6 | G20: 0.7-0.775 | H20: 2 | J20: 0.7-0.775 | K20: 0
A21: 0.775-0.85 | B21: 19 | D21: 0.775-0.85 | E21: 7 | G21: 0.775-0.85 | H21: 7 | J21: 0.775-0.85 | K21: 5
A22: 0.85-0.925 | B22: 11 | D22: 0.85-0.925 | E22: 1 | G22: 0.85-0.925 | H22: 6 | J22: 0.85-0.925 | K22: 4
A23: 0.925-1 | B23: 22 | D23: 0.925-1 | E23: 5 | G23: 0.925-1 | H23: 3 | J23: 0.925-1 | K23: 14
A24: 1-1.075 | B24: 4 | D24: 1-1.075 | E24: 0 | G24: 1-1.075 | H24: 1 | J24: 1-1.075 | K24: 3
A25: 1.075-1.15 | B25: 1 | D25: 1.075-1.15 | E25: 0 | G25: 1.075-1.15 | H25: 1 | J25: 1.075-1.15 | K25: 0
A26: Total | B26: 80 | D26: Total | E26: 27 | G26: Total | H26: 26 | J26: Total | K26: 27
A28: Frequency Percentage Distribution
A29: Class | B29: Overall | C29: High | D29: Mid | E29: Low
A30: 0.44-0.515 | B30: =B16/B$26 -> 0.0375 | C30: =E16/$E$26 -> 0 | D30: =H16/$H$26 -> 0.11538462 | E30: =K16/$K$26 -> 0
A31: 0.515-0.59 | B31: =B17/B$26 -> 0.025 | C31: =E17/$E$26 -> 0 | D31: =H17/$H$26 -> 0.076923077 | E31: =K17/$K$26 -> 0
A32: 0.59-0.665 | B32: =B18/B$26 -> 0.05 | C32: =E18/$E$26 -> 0.14814815 | D32: =H18/$H$26 -> 0 | E32: =K18/$K$26 -> 0
A33: 0.665-0.74 | B33: =B19/B$26 -> 0.075 | C33: =E19/$E$26 -> 0.14814815 | D33: =H19/$H$26 -> 0.076923077 | E33: =K19/$K$26 -> 0
A34: 0.74-0.815 | B34: =B20/B$26 -> 0.1 | C34: =E20/$E$26 -> 0.22222222 | D34: =H20/$H$26 -> 0.076923077 | E34: =K20/$K$26 -> 0
A35: 0.815-0.89 | B35: =B21/B$26 -> 0.2375 | C35: =E21/$E$26 -> 0.25925926 | D35: =H21/$H$26 -> 0.26923077 | E35: =K21/$K$26 -> 0.18518519
A36: 0.89-0.965 | B36: =B22/B$26 -> 0.1375 | C36: =E22/$E$26 -> 0.037037037 | D36: =H22/$H$26 -> 0.23076923 | E36: =K22/$K$26 -> 0.14814815
A37: 0.965-1.04 | B37: =B23/B$26 -> 0.275 | C37: =E23/$E$26 -> 0.18518519 | D37: =H23/$H$26 -> 0.11538462 | E37: =K23/$K$26 -> 0.51851852
A38: 1.04-1.115 | B38: =B24/B$26 -> 0.05 | C38: =E24/$E$26 -> 0 | D38: =H24/$H$26 -> 0.038461538 | E38: =K24/$K$26 -> 0.11111111

Sheet PairWiase Data
A1: Criterion Variable Group Data
G2: Sample Variance | L2: Variance | M2: Sample Size
B3: Low | C3: Mid | D3: High | G3: Low | H3: Mid | I3: High | K3: Low | L3: 0.0043170141 | M3: 26
B4: 0.96131147 | C4: 0.90960448 | D4: 0.82313457 | G4: =_xlfn.VAR.S(B4:B29) -> 0.0043170141 | H4: =_xlfn.VAR.S(C4:C30) -> 0.031451289 | I4: =_xlfn.VAR.S(D4:D30) -> 0.015327687 | K4: Mid | L4: 0.031451289 | M4: 27
B5: 0.9731073 | C5: 1.0991592 | D5: 0.80665475 | K5: High | L5: 0.015327687 | M5: 27 | O5: t-Test: Two-Sample Assuming Unequal Variances | S5: t-Test: Two-Sample Assuming Unequal Variances | W5: t-Test: Two-Sample Assuming Unequal Variances
B6: 0.82456469 | C6: 0.90750238 | D6: 0.81229289 | G6: Sample Size
B7: 0.83014906 | C7: 0.99557676 | D7: 0.81691703 | G7: Low | H7: Mid | I7: High | P7: Low | Q7: Mid | T7: Low | U7: High | X7: Mid | Y7: High
B8: 0.8425089 | C8: 1.0293968 | D8: 0.89645316 | G8: =COUNT(B4:B29) -> 26 | H8: =COUNT(C4:C30) -> 27 | I8: =COUNT(D4:D30) -> 27 | O8: Mean | P8: 0.93706695 | Q8: 0.78892807 | S8: Mean | T8: 0.93706695 | U8: 0.76890841 | W8: Mean | X8: 0.78892807 | Y8: 0.76890841
B9: 0.95078038 | C9: 0.74765985 | D9: 0.74393593 | O9: Variance | P9: 0.0043170141 | Q9: 0.031451289 | S9: Variance | T9: 0.0043170141 | U9: 0.015327687 | W9: Variance | X9: 0.031451289 | Y9: 0.015327687
B10: 0.92043994 | C10: 0.94171913 | D10: 0.80232293 | O10: Observations | P10: 26 | Q10: 27 | S10: Observations | T10: 26 | U10: 27 | W10: Observations | X10: 27 | Y10: 27
B11: 0.97351588 | C11: 0.83068333 | D11: 0.70847724 | G11: Variance Test F-Stat | O11: Hypothesized Mean Difference | P11: 0 | S11: Hypothesized Mean Difference | T11: 0 | W11: Hypothesized Mean Difference | X11: 0
B12: 0.97000635 | C12: 0.81881908 | D12: 0.66420472 | H12: Low | I12: Mid | O12: df | P12: 33 | S12: df | T12: 40 | W12: df | X12: 46
B13: 1.0333881 | C13: 0.85124913 | D13: 0.67668244 | G13: Mid | H13: =L3/L4 -> 0.13726032 | O13: t Stat | P13: 4.0606548 | S13: t Stat | T13: 6.207982 | W13: t Stat | X13: 0.4809648
B14: 0.82697733 | C14: 0.81321442 | D14: 0.59272337 | G14: High | H14: =L3/L5 -> 0.28164811 | I14: =L4/L5 -> 2.0519266 | O14: P(T<=t) one-tail | P14: 0.00014157291 | S14: P(T<=t) one-tail | T14: 1.2052602e-07 | W14: P(T<=t) one-tail | X14: 0.3164107
B15: 0.91691534 | C15: 0.8518742 | D15: 0.58570958 | O15: t Critical one-tail | P15: 1.6923603 | S15: t Critical one-tail | T15: 1.683851 | W15: t Critical one-tail | X15: 1.6786604
B16: 0.87966178 | C16: 0.84705863 | D16: 0.59927575 | O16: P(T<=t) two-tail | P16: 0.00028314583 | S16: P(T<=t) two-tail | T16: 2.4105204e-07 | W16: P(T<=t) two-tail | X16: 0.6328214
B17: 0.9415911 | C17: 0.87160473 | D17: 0.59639727 | G17: P-Values | O17: t Critical two-tail | P17: 2.0345153 | S17: t Critical two-tail | T17: 2.0210754 | W17: t Critical two-tail | X17: 2.0128956
B18: 0.98611877 | C18: 0.67896377 | D18: 0.63033084 | H18: Low | I18: Mid
B19: 0.97603252 | C19: 0.69880993 | D19: 0.68967624 | G19: Mid | H19: =_xlfn.F.DIST(H13,G8-1,H8-1,1) -> 2.0725357e-06
B20: 0.93110018 | C20: 0.72919736 | D20: 0.70525719 | G20: High | H20: =_xlfn.F.DIST(H14,G8-1,I8-1,1) -> 0.0011180623 | I20: =_xlfn.F.DIST(I14,H8-1,I8-1,1) -> 0.96376869 | O20: ME | P20: {=SQRT(H42(P9/P10)+(Q9/Q10))*P17} -> #REF! | S20: ME | T20: =SQRT((T9/T10)+(U9/U10))*T17 -> 0.054745822 | W20: ME | X20: =SQRT((X9/X10)+(Y9/Y10))*X17 -> 0.083784701
B21: 0.96845255 | C21: 0.47096725 | D21: 0.72710286 | O21: UCL | P21: =P8-Q8+P20 -> #REF! | S21: UCL | T21: =T8-U8+T20 -> 0.22290436 | W21: UCL | X21: =X8-Y8+X20 -> 0.10380436
B22: 1.0458094 | C22: 0.44641572 | D22: 0.71683258 | O22: LCL | P22: =P8-Q8-P20 -> #REF! | S22: LCL | T22: =T8-U8-T20 -> 0.11341271 | W22: LCL | X22: =X8-Y8-X20 -> -0.063765038
B23: 0.90532465 | C23: 0.46687932 | D23: 0.81821054 | G23: Conclusion: Reject if P-value is greater than 0.95 or less than 0.05
B24: 0.82460695 | C24: 0.49378446 | D24: 0.99087828 | H24: Low | I24: Mid
B25: 0.98537598 | C25: 0.51744125 | D25: 0.94972539 | G25: Mid | H25: =IF(OR(H19<0.05,H19>0.95),"Reject","F.T.R") -> Reject
B26: 0.94009104 | C26: 0.79569988 | D26: 0.97724445 | G26: High | H26: =IF(OR(H20<0.05,H20>0.95),"Reject","F.T.R") -> Reject | I26: =IF(OR(I20<0.05,I20>0.95),"Reject","F.T.R") -> Reject
B27: 0.9521891 | C27: 0.82481096 | D27: 0.95019002
B28: 1.0443985 | C28: 0.84479984 | D28: 0.94359671 | H28: Variances assumed NOT equal
B29: 0.95932334 | C29: 0.85454799 | D29: 0.75189779
C30: 0.9636181 | D30: 0.78440255
G31: Pair-Wise Confidences Intervals for Differnces in Means
G32: 95% Confidence Intervals
I33: Low | J33: Mid | L33: 0.0011180623
G34: Mid | H34: UCL | I34: 0.22236109
H35: LCL | I35: 0.073916655
G36: High | H36: UCL | I36: 0.22290436 | J36: 0.10380436
H37: LCL | I37: 0.11341271 | J37: -0.063765038
G39: Pair-Wise Hypothesis Tests for Differences in Means
G40: t-statistics
H41: Low | I41: Mid
...

Sheet Group logs
A1: Low Density | D1: Mid Density | G1: High Density | L1: Log Data | M1: Low Density | P1: Mid Density | S1: High Density
B2: WastePC | C2: IncomePC | E2: WastePC | F2: IncomePC | H2: WastePC | I2: IncomePC | M2: WastePC | N2: IncomePC | P2: WastePC | Q2: IncomePC | S2: WastePC | T2: IncomePC | X2: Low Density LN | AJ2: Low Density
B3: 0.96131147 | C3: 49169.113 | E3: 0.90960448 | F3: 42578.37 | H3: 0.82313457 | I3: 59848.367 | M3: =LN(B3) -> -0.03945681 | N3: =LN(C3) -> 10.803021 | P3: =LN(E3) -> -0.094745412 | Q3: =LN(F3) -> 10.659102 | S3: =LN(H3) -> -0.19463558 | T3: =LN(I3) -> 10.999569 | X3: SUMMARY OUTPUT | AJ3: SUMMARY OUTPUT
B4: 0.9731073 | C4: 48630.653 | E4: 1.0991592 | F4: 42967.354 | H4: 0.80665475 | I4: 61999.536 | M4: =LN(B4) -> -0.027260924 | N4: =LN(C4) -> 10.792009 | P4: =LN(E4) -> 0.094545538 | Q4: =LN(F4) -> 10.668196 | S4: =LN(H4) -> -0.21485952 | T4: =LN(I4) -> 11.034882
B5: 0.82456469 | C5: 50947.705 | E5: 0.90750238 | F5: 43633.293 | H5: 0.81229289 | I5: 63842.272 | M5: =LN(B5) -> -0.19289968 | N5: =LN(C5) -> 10.838555 | P5: =LN(E5) -> -0.097059089 | Q5: =LN(F5) -> 10.683576 | S5: =LN(H5) -> -0.20789431 | T5: =LN(I5) -> 11.064171 | X5: Regression Statistics | AJ5: Regression Statistics
B6: 0.83014906 | C6: 53623.497 | E6: 0.99557676 | F6: 45312.989 | H6: 0.81691703 | I6: 64548.28 | M6: =LN(B6) -> -0.18615 | N6: =LN(C6) -> 10.889743 | P6: =LN(E6) -> -0.0044330546 | Q6: =LN(F6) -> 10.721349 | S6: =LN(H6) -> -0.20221774 | T6: =LN(I6) -> 11.075169 | X6: Multiple R | Y6: 0.051808976 | AJ6: Multiple R | AK6: 0.0098867248
B7: 0.8425089 | C7: 55484.86 | E7: 1.0293968 | F7: 45968.22 | H7: 0.89645316 | I7: 67653.011 | M7: =LN(B7) -> -0.17137105 | N7: =LN(C7) -> 10.923865 | P7: =LN(E7) -> 0.028973027 | Q7: =LN(F7) -> 10.735706 | S7: =LN(H7) -> -0.10930923 | T7: =LN(I7) -> 11.122147 | X7: R Square | Y7: 0.0026841699 | AJ7: R Square | AK7: 9.7747327e-05
B8: 0.95078038 | C8: 33898.355 | E8: 0.74765985 | F8: 45394.973 | H8: 0.74393593 | I8: 57455.652 | M8: =LN(B8) -> -0.050472184 | N8: =LN(C8) -> 10.431122 | P8: =LN(E8) -> -0.29080715 | Q8: =LN(F8) -> 10.723157 | S8: =LN(H8) -> -0.29580036 | T8: =LN(I8) -> 10.958769 | X8: Adjusted R Square | Y8: -0.038870656 | AJ8: Adjusted R Square | AK8: -0.041564847
B9: 0.92043994 | C9: 34766.122 | E9: 0.94171913 | F9: 46308.538 | H9: 0.80232293 | I9: 59243.148 | M9: =LN(B9) -> -0.08290353 | N9: =LN(C9) -> 10.456399 | P9: =LN(E9) -> -0.060048216 | Q9: =LN(F9) -> 10.743082 | S9: =LN(H9) -> -0.22024409 | T9: =LN(I9) -> 10.989405 | X9: Standard Error | Y9: 0.07270943 | AJ9: Standard Error | AK9: 0.067055575
B10: 0.97351588 | C10: 36137.147 | E10: 0.83068333 | F10: 48422.439 | H10: 0.70847724 | I10: 60420.583 | M10: =LN(B10) -> -0.026841141 | N10: =LN(C10) -> 10.495077 | P10: =LN(E10) -> -0.18550663 | Q10: =LN(F10) -> 10.787719 | S10: =LN(H10) -> -0.34463734 | T10: =LN(I10) -> 11.009085 | X10: Observations | Y10: 26 | AJ10: Observations | AK10: 26
B11: 0.97000635 | C11: 38154.285 | E11: 0.81881908 | F11: 49493.721 | H11: 0.66420472 | I11: 60665.397 | M11: =LN(B11) -> -0.030452657 | N11: =LN(C11) -> 10.549393 | P11: =LN(E11) -> -0.19989212 | Q11: =LN(F11) -> 10.809601 | S11: =LN(H11) -> -0.40916486 | T11: =LN(I11) -> 11.013129
B12: 1.0333881 | C12: 39961.976 | E12: 0.85124913 | F12: 50977.923 | H12: 0.67668244 | I12: 61464.366 | M12: =LN(B12) -> 0.032842789 | N12: =LN(C12) -> 10.595684 | P12: =LN(E12) -> -0.16105045 | Q12: =LN(F12) -> 10.839148 | S12: =LN(H12) -> -0.39055319 | T12: =LN(I12) -> 11.026213 | X12: ANOVA | AJ12: ANOVA
B13: 0.82697733 | C13: 42781.479 | E13: 0.81321442 | F13: 43631.083 | H13: 0.59272337 | I13: 48906.146 | M13: =LN(B13) -> -0.18997799 | N13: =LN(C13) -> 10.663861 | P13: =LN(E13) -> -0.20676047 | Q13: =LN(F13) -> 10.683525 | S13: =LN(H13) -> -0.52302748 | T13: =LN(I13) -> 10.797658 | Y13: df | Z13: SS | AA13: MS | AB13: F | AC13: Significance F | AK13: df | AL13: SS | AM13: MS | AN13: F | AO13: Significance F
B14: 0.91691534 | C14: 44588.918 | E14: 0.8518742 | F14: 45054.361 | H14: 0.58570958 | I14: 50140.165 | M14: =LN(B14) -> -0.086740133 | N14: =LN(C14) -> 10.705241 | P14: =LN(E14) -> -0.16031642 | Q14: =LN(F14) -> 10.715625 | S14: =LN(H14) -> -0.53493122 | T14: =LN(I14) -> 10.822578 | X14: Regression | Y14: 1 | Z14: 0.00034148373 | AA14: 0.00034148373 | AB14: 0.064593459 | AC14: 0.80154266 | AJ14: Regression | AK14: 1 | AL14: 1.0549415e-05 | AM14: 1.0549415e-05 | AN14: 0.0023461652 | AO14: 0.96176863
B15: 0.87966178 | C15: 46518.911 | E15: 0.84705863 | F15: 46975.877 | H15: 0.59927575 | I15: 49702.804 | M15: =LN(B15) -> -0.12821779 | N15: =LN(C15) -> 10.747614 | P15: =LN(E15) -> -0.16598537 | Q15: =LN(F15) -> 10.75739 | S15: =LN(H15) -> -0.51203344 | T15: =LN(I15) -> 10.813817 | X15: Residual | Y15: 24 | Z15: 0.12687987 | AA15: 0.0052866612 | AJ15: Residual | AK15: 24 | AL15: 0.1079148 | AM15: 0.0044964502
B16: 0.9415911 | C16: 46916.693 | E16: 0.87160473 | F16: 48178.51 | H16: 0.59639727 | I16: 50558.07 | M16: =LN(B16) -> -0.060184171 | N16: =LN(C16) -> 10.756129 | P16: =LN(E16) -> -0.13741925 | Q16: =LN(F16) -> 10.782668 | S16: =LN(H16) -> -0.51684827 | T16: =LN(I16) -> 10.830878 | X16: Total | Y16: 25 | Z16: 0.12722135 | AJ16: Total | AK16: 25 | AL16: 0.10792535
B17: 0.98611877 | C17: 48441.571 | E17: 0.67896377 | F17: 44071.315 | H17: 0.63033084 | I17: 51635.958 | M17: =LN(B17) -> -0.013978471 | N17: =LN(C17) -> 10.788114 | P17: =LN(E17) -> -0.38718751 | Q17: =LN(F17) -> 10.693564 | S17: =LN(H17) -> -0.46151045 | T17: =LN(I17) -> 10.851974
B18: 0.97603252 | C18: 50618.011 | E18: 0.69880993 | F18: 44815.502 | H18: 0.68967624 | I18: 28162.493 | M18: =LN(B18) -> -0.024259371 | N18: =LN(C18) -> 10.832063 | P18: =LN(E18) -> -0.35837649 | Q18: =LN(F18) -> 10.710309 | S18: =LN(H18) -> -0.371533 | T18: =LN(I18) -> 10.245746 | Y18: Coefficients | Z18: Standard Error | AA18: t Stat | AB18: P-value | AC18: Lower 95% | AD18: Upper 95% | AE18: Lower 95.0% | AF18: Upper 95.0% | AK18: Coefficients | AL18: Standard Error | AM18: t Stat | AN18: P-value | AO18: Lower 95% | AP18: Upper 95% | AQ18: Lower 95.0% | AR18: Upper 95.0%
B19: 0.93110018 | C19: 72220.477 | E19: 0.72919736 | F19: 45516.517 | H19: 0.70525719 | I19: 28600.627 | M19: =LN(B19) -> -0.0713884 | N19: =LN(C19) -> 11.187479 | P19: =LN(E19) -> -0.31581085 | Q19: =LN(F19) -> 10.725831 | S19: =LN(H19) -> -0.34919274 | T19: =LN(I19) -> 10.261184 | X19: Intercept | Y19: 0.093314118 | Z19: 0.63258579 | AA19: 0.14751219 | AB19: 0.88396002 | AC19: -1.2122788 | AD19: 1.398907 | AE19: -1.2122788 | AF19: 1.398907 | AJ19: Intercept | AK19: 0.93951873 | AL19: 0.052298102 | AM19: 17.964681 | AN19: 2.0150931e-15 | AO19: 0.83158075 | AP19: 1.0474567 | AQ19: 0.83158075 | AR19: 1.0474567
B20: 0.96845255 | C20: 82643.83 | E20: 0.47096725 | F20: 36325.798 | H20: 0.72710286 | I20: 29307.706 | M20: =LN(B20) -> -0.032055786 | N20: =LN(C20) -> 11.322295 | P20: =LN(E20) -> -0.75296672 | Q20: =LN(F20) -> 10.500283 | S20: =LN(H20) -> -0.31868733 | T20: =LN(I20) -> 10.285606 | X20: IncomePC | Y20: -0.014830109 | Z20: 0.058351238 | AA20: -0.25415243 | AB20: 0.80154266 | AC20: -0.13526114 | AD20: 0.10560093 | AE20: -0.13526114 | AF20: 0.10560093 | AJ20: IncomePC | AK20: -4.6672303e-08 | AL20: 9.635626e-07 | AM20: -0.048437229 | AN20: 0.96176863 | AO20: -2.0353678e-06 | AP20: 1.9420232e-06 | AQ20: -2.0353678e-06 | AR20: 1.9420232e-06
B21: 1.0458094 | C21: 84967.927 | E21: 0.44641572 | F21: 37029.425 | H21: 0.71683258 | I21: 32266.419 | M21: =LN(B21) -> 0.044791171 | N21: =LN(C21) -> 11.350029 | P21: =LN(E21) -> -0.80650466 | Q21: =LN(F21) -> 10.519468 | S21: =LN(H21) -> -0.33291297 | T21: =LN(I21) -> 10.381782
B22: 0.90532465 | C22: 70605.994 | E22: 0.46687932 | F22: 38606.127 | H22: 0.81821054 | I22: 34062.014 | M22: =LN(B22) -> -0.099461668 | N22: =LN(C22) -> 11.16487 | P22: =LN(E22) -> -0.76168448 | Q22: =LN(F22) -> 10.561166 | S22: =LN(H22) -> -0.20063559 | T22: =LN(I22) -> 10.435938
B23: 0.82460695 | C23: 75649.891 | E23: 0.49378446 | F23: 41040.089 | H23: 0.99087828 | I23: 57103.105 | M23: =LN(B23) -> -0.19284843 | N23: =LN(C23) -> 11.233871 | P23: =LN(E23) -> -0.70565617 | Q23: =LN(F23) -> 10.622305 | S23: =LN(H23) -> -0.0091635821 | T23: =LN(I23) -> 10.952614 | X23: Mid Density LN | AJ23: Mid Density
B24: 0.98537598 | C24: 46855.153 | E24: 0.51744125 | F24: 42384.192 | H24: 0.94972539 | I24: 58794.715 | M24: =LN(B24) -> -0.014732008 | N24: =LN(C24) -> 10.754816 | P24: =LN(E24) -> -0.65885928 | Q24: =LN(F24) -> 10.654531 | S24: =LN(H24) -> -0.051582396 | T24: =LN(I24) -> 10.981807 | X24: SUMMARY OUTPUT | AJ24: SUMMARY OUTPUT
B25: 0.94009104 | C25: 49950.928 | E25: 0.79569988 | F25: 42235.7 | H25: 0.97724445 | I25: 60097.331 | M25: =LN(B25) -> -0.06177856 | N25: =LN(C25) -> 10.818796 | P25: =LN(E25) -> -0.2285332 | Q25: =LN(F25) -> 10.651021 | S25: =LN(H25) -> -0.02301845 | T25: =LN(I25) -> 11.003721
B26: 0.9521891 | C26: 51968.936 | E26: 0.82481096 | F26: 42753.277 | H26: 0.95019002 | I26: 61165.315 | M26: =LN(B26) -> -0.048991628 | N26: =LN(C26) -> 10.858401 | P26: =LN(E26) -> -0.19260106 | Q26: =LN(F26) -> 10.663201 | S26: =LN(H26) -> -0.051093297 | T26: =LN(I26) -> 11.021336 | X26: Regression Statistics | AJ26: Regression Statistics
B27: 1.0443985 | C27: 54530.911 | E27: 0.84479984 | F27: 43111.71 | H27: 0.94359671 | I27: 63034.997 | M27: =LN(B27) -> 0.043441085 | N27: =LN(C27) -> 10.906523 | P27: =LN(E27) -> -0.16865555 | Q27: =LN(F27) -> 10.67155 | S27: =LN(H27) -> -0.058056421 | T27: =LN(I27) -> 11.051445 | X27: Multiple R | Y27: 0.70296703 | AJ27: Multiple R | AK27: 0.63109803
B28: 0.95932334 | C28: 55793.935 | E28: 0.85454799 | F28: 45221.768 | H28: 0.75189779 | I28: 46737.628 | M28: =LN(B28) -> -0.041527098 | N28: =LN(C28) -> 10.92942 | P28: =LN(E28) -> -0.15718261 | Q28: =LN(F28) -> 10.719334 | S28: =LN(H28) -> -0.28515488 | T28: =LN(I28) -> 10.752305 | X28: R Square | Y28: 0.49416265 | AJ28: R Square | AK28: 0.39828472
E29: 0.9636181 | F29: 46318.331 | H29: 0.78440255 | I29: 48075.766 | P29: =LN(E29) -> -0.037060224 | Q29: =LN(F29) -> 10.743293 | S29: =LN(H29) -> -0.24283293 | T29: =LN(I29) -> 10.780533 | X29: Adjusted R Square | Y29: 0.47392916 | AJ29: Adjusted R Square | AK29: 0.37421611
X30: Standard Error | Y30: 0.18427321 | AJ30: Standard Error | AK30: 0.14029152
X31: Observations | Y31: 27 | AJ31: Observations | AK31: 27
X33: ANOVA | AJ33: ANOVA
Y34: df | Z34: SS | AA34: MS | AB34: F | AC34: Significance F | AK34: df | AL34: SS | AM34: MS | AN34: F | AO34: Significance F
X35: Regression | Y35: 1 | Z35: 0.82932247 | AA35: 0.82932247 | AB35: 24.423001 | AC35: 4.3311799e-05 | AJ35: Regression | AK35: 1 | AL35: 0.32569077 | AM35: 0.32569077 | AN35: 16.54789 | AO35: 0.00041607518
X36: Residual | Y36: 25 | Z36: 0.84891539 | AA36: 0.033956616 | AJ36: Residual | AK36: 25 | AL36: 0.49204275 | AM36: 0.01968171
X37: Total | Y37: 26 | Z37: 1.6782379 | AJ37: Total | AK37: 26 | AL37: 0.81773352
Y39: Coefficients | Z39: Standard Error | AA39: t Stat | AB39: P-value | AC39: Lower 95% | AD39: Upper 95% | AE39: Lower 95.0% | AF39: Upper 95.0% | AK39: Coefficients | AL39: Standard Error | AM39: t Stat | AN39: P-value | AO39: Lower 95% | AP39: Upper 95% | AQ39: Lower 95.0% | AR39: Upper 95.0%
